[38;5;127mlibs[0m/[38;5;172mnvidia-cuda[0m/[38;5;67m11.2.0[0m/[38;5;68mbin[0m
 |
 [0;32mOK[0m
Mon Mar  4 15:45:10 2024       
+---------------------------------------------------------------------------------------+
| NVIDIA-SMI 535.154.05             Driver Version: 535.154.05   CUDA Version: 12.2     |
|-----------------------------------------+----------------------+----------------------+
| GPU  Name                 Persistence-M | Bus-Id        Disp.A | Volatile Uncorr. ECC |
| Fan  Temp   Perf          Pwr:Usage/Cap |         Memory-Usage | GPU-Util  Compute M. |
|                                         |                      |               MIG M. |
|=========================================+======================+======================|
|   0  NVIDIA A100-PCIE-40GB          Off | 00000000:49:00.0 Off |                    0 |
| N/A   40C    P0              37W / 250W |      0MiB / 40960MiB |      0%      Default |
|                                         |                      |             Disabled |
+-----------------------------------------+----------------------+----------------------+
                                                                                         
+---------------------------------------------------------------------------------------+
| Processes:                                                                            |
|  GPU   GI   CI        PID   Type   Process name                            GPU Memory |
|        ID   ID                                                             Usage      |
|=======================================================================================|
|  No running processes found                                                           |
+---------------------------------------------------------------------------------------+
[nltk_data] Downloading package punkt to /users/adbt150/nltk_data...
[nltk_data]   Package punkt is already up-to-date!
Selected Tasks: ['gsm8k']
Loading checkpoint shards:   0%|          | 0/2 [00:00<?, ?it/s]Loading checkpoint shards:  50%|â–ˆâ–ˆâ–ˆâ–ˆâ–ˆ     | 1/2 [00:00<00:00,  8.20it/s]Loading checkpoint shards: 100%|â–ˆâ–ˆâ–ˆâ–ˆâ–ˆâ–ˆâ–ˆâ–ˆâ–ˆâ–ˆ| 2/2 [00:00<00:00,  8.75it/s]Loading checkpoint shards: 100%|â–ˆâ–ˆâ–ˆâ–ˆâ–ˆâ–ˆâ–ˆâ–ˆâ–ˆâ–ˆ| 2/2 [00:00<00:00,  8.66it/s]
Task: gsm8k; number of docs: 1319
Traceback (most recent call last):
  File "/users/adbt150/miniconda3/envs/llm/lib/python3.9/site-packages/nltk/corpus/util.py", line 84, in __load
    root = nltk.data.find(f"{self.subdir}/{zip_name}")
  File "/users/adbt150/miniconda3/envs/llm/lib/python3.9/site-packages/nltk/data.py", line 583, in find
    raise LookupError(resource_not_found)
LookupError: 
**********************************************************************
  Resource [93mwordnet[0m not found.
  Please use the NLTK Downloader to obtain the resource:

  [31m>>> import nltk
  >>> nltk.download('wordnet')
  [0m
  For more information see: https://www.nltk.org/data.html

  Attempted to load [93mcorpora/wordnet.zip/wordnet/[0m

  Searched in:
    - '/users/adbt150/nltk_data'
    - '/users/adbt150/miniconda3/envs/llm/nltk_data'
    - '/users/adbt150/miniconda3/envs/llm/share/nltk_data'
    - '/users/adbt150/miniconda3/envs/llm/lib/nltk_data'
    - '/usr/share/nltk_data'
    - '/usr/local/share/nltk_data'
    - '/usr/lib/nltk_data'
    - '/usr/local/lib/nltk_data'
**********************************************************************


During handling of the above exception, another exception occurred:

Traceback (most recent call last):
  File "/users/adbt150/lm-evaluation-harness/main.py", line 117, in <module>
    main()
  File "/users/adbt150/lm-evaluation-harness/main.py", line 76, in main
    results = evaluator.simple_evaluate(
  File "/users/adbt150/lm-evaluation-harness/lm_eval/utils.py", line 243, in _wrapper
    return fn(*args, **kwargs)
  File "/users/adbt150/lm-evaluation-harness/lm_eval/evaluator.py", line 114, in simple_evaluate
    results = evaluate(
  File "/users/adbt150/lm-evaluation-harness/lm_eval/utils.py", line 243, in _wrapper
    return fn(*args, **kwargs)
  File "/users/adbt150/lm-evaluation-harness/lm_eval/evaluator.py", line 336, in evaluate
    doc['question'] = p.verbSynonyms(doc['question'])
  File "/users/adbt150/lm-evaluation-harness/lm_eval/permutations.py", line 73, in verbSynonyms
    synonyms = getSynonym(token.text)
  File "/users/adbt150/lm-evaluation-harness/lm_eval/permutations.py", line 53, in getSynonym
    synsets = wordnet.synsets(word, pos=wordnet.VERB)
  File "/users/adbt150/miniconda3/envs/llm/lib/python3.9/site-packages/nltk/corpus/util.py", line 121, in __getattr__
    self.__load()
  File "/users/adbt150/miniconda3/envs/llm/lib/python3.9/site-packages/nltk/corpus/util.py", line 86, in __load
    raise e
  File "/users/adbt150/miniconda3/envs/llm/lib/python3.9/site-packages/nltk/corpus/util.py", line 81, in __load
    root = nltk.data.find(f"{self.subdir}/{self.__name}")
  File "/users/adbt150/miniconda3/envs/llm/lib/python3.9/site-packages/nltk/data.py", line 583, in find
    raise LookupError(resource_not_found)
LookupError: 
**********************************************************************
  Resource [93mwordnet[0m not found.
  Please use the NLTK Downloader to obtain the resource:

  [31m>>> import nltk
  >>> nltk.download('wordnet')
  [0m
  For more information see: https://www.nltk.org/data.html

  Attempted to load [93mcorpora/wordnet[0m

  Searched in:
    - '/users/adbt150/nltk_data'
    - '/users/adbt150/miniconda3/envs/llm/nltk_data'
    - '/users/adbt150/miniconda3/envs/llm/share/nltk_data'
    - '/users/adbt150/miniconda3/envs/llm/lib/nltk_data'
    - '/usr/share/nltk_data'
    - '/usr/local/share/nltk_data'
    - '/usr/lib/nltk_data'
    - '/usr/local/lib/nltk_data'
**********************************************************************

[nltk_data] Downloading package punkt to /users/adbt150/nltk_data...
[nltk_data]   Package punkt is already up-to-date!
Selected Tasks: ['hellaswag']
Loading checkpoint shards:   0%|          | 0/2 [00:00<?, ?it/s]Loading checkpoint shards:  50%|â–ˆâ–ˆâ–ˆâ–ˆâ–ˆ     | 1/2 [00:00<00:00,  8.55it/s]Loading checkpoint shards: 100%|â–ˆâ–ˆâ–ˆâ–ˆâ–ˆâ–ˆâ–ˆâ–ˆâ–ˆâ–ˆ| 2/2 [00:00<00:00,  8.36it/s]Loading checkpoint shards: 100%|â–ˆâ–ˆâ–ˆâ–ˆâ–ˆâ–ˆâ–ˆâ–ˆâ–ˆâ–ˆ| 2/2 [00:00<00:00,  8.38it/s]
Task: hellaswag; number of docs: 10042
Traceback (most recent call last):
  File "/users/adbt150/miniconda3/envs/llm/lib/python3.9/site-packages/nltk/corpus/util.py", line 84, in __load
    root = nltk.data.find(f"{self.subdir}/{zip_name}")
  File "/users/adbt150/miniconda3/envs/llm/lib/python3.9/site-packages/nltk/data.py", line 583, in find
    raise LookupError(resource_not_found)
LookupError: 
**********************************************************************
  Resource [93mwordnet[0m not found.
  Please use the NLTK Downloader to obtain the resource:

  [31m>>> import nltk
  >>> nltk.download('wordnet')
  [0m
  For more information see: https://www.nltk.org/data.html

  Attempted to load [93mcorpora/wordnet.zip/wordnet/[0m

  Searched in:
    - '/users/adbt150/nltk_data'
    - '/users/adbt150/miniconda3/envs/llm/nltk_data'
    - '/users/adbt150/miniconda3/envs/llm/share/nltk_data'
    - '/users/adbt150/miniconda3/envs/llm/lib/nltk_data'
    - '/usr/share/nltk_data'
    - '/usr/local/share/nltk_data'
    - '/usr/lib/nltk_data'
    - '/usr/local/lib/nltk_data'
**********************************************************************


During handling of the above exception, another exception occurred:

Traceback (most recent call last):
  File "/users/adbt150/lm-evaluation-harness/main.py", line 117, in <module>
    main()
  File "/users/adbt150/lm-evaluation-harness/main.py", line 76, in main
    results = evaluator.simple_evaluate(
  File "/users/adbt150/lm-evaluation-harness/lm_eval/utils.py", line 243, in _wrapper
    return fn(*args, **kwargs)
  File "/users/adbt150/lm-evaluation-harness/lm_eval/evaluator.py", line 114, in simple_evaluate
    results = evaluate(
  File "/users/adbt150/lm-evaluation-harness/lm_eval/utils.py", line 243, in _wrapper
    return fn(*args, **kwargs)
  File "/users/adbt150/lm-evaluation-harness/lm_eval/evaluator.py", line 314, in evaluate
    doc['query'] = p.verbSynonyms(doc['query'])
  File "/users/adbt150/lm-evaluation-harness/lm_eval/permutations.py", line 73, in verbSynonyms
    synonyms = getSynonym(token.text)
  File "/users/adbt150/lm-evaluation-harness/lm_eval/permutations.py", line 53, in getSynonym
    synsets = wordnet.synsets(word, pos=wordnet.VERB)
  File "/users/adbt150/miniconda3/envs/llm/lib/python3.9/site-packages/nltk/corpus/util.py", line 121, in __getattr__
    self.__load()
  File "/users/adbt150/miniconda3/envs/llm/lib/python3.9/site-packages/nltk/corpus/util.py", line 86, in __load
    raise e
  File "/users/adbt150/miniconda3/envs/llm/lib/python3.9/site-packages/nltk/corpus/util.py", line 81, in __load
    root = nltk.data.find(f"{self.subdir}/{self.__name}")
  File "/users/adbt150/miniconda3/envs/llm/lib/python3.9/site-packages/nltk/data.py", line 583, in find
    raise LookupError(resource_not_found)
LookupError: 
**********************************************************************
  Resource [93mwordnet[0m not found.
  Please use the NLTK Downloader to obtain the resource:

  [31m>>> import nltk
  >>> nltk.download('wordnet')
  [0m
  For more information see: https://www.nltk.org/data.html

  Attempted to load [93mcorpora/wordnet[0m

  Searched in:
    - '/users/adbt150/nltk_data'
    - '/users/adbt150/miniconda3/envs/llm/nltk_data'
    - '/users/adbt150/miniconda3/envs/llm/share/nltk_data'
    - '/users/adbt150/miniconda3/envs/llm/lib/nltk_data'
    - '/usr/share/nltk_data'
    - '/usr/local/share/nltk_data'
    - '/usr/lib/nltk_data'
    - '/usr/local/lib/nltk_data'
**********************************************************************

[nltk_data] Downloading package punkt to /users/adbt150/nltk_data...
[nltk_data]   Package punkt is already up-to-date!
Selected Tasks: ['truthfulqa_mc']
Loading checkpoint shards:   0%|          | 0/2 [00:00<?, ?it/s]Loading checkpoint shards:  50%|â–ˆâ–ˆâ–ˆâ–ˆâ–ˆ     | 1/2 [00:00<00:00,  7.89it/s]Loading checkpoint shards: 100%|â–ˆâ–ˆâ–ˆâ–ˆâ–ˆâ–ˆâ–ˆâ–ˆâ–ˆâ–ˆ| 2/2 [00:00<00:00,  8.48it/s]Loading checkpoint shards: 100%|â–ˆâ–ˆâ–ˆâ–ˆâ–ˆâ–ˆâ–ˆâ–ˆâ–ˆâ–ˆ| 2/2 [00:00<00:00,  8.38it/s]
Task: truthfulqa_mc; number of docs: 817
Traceback (most recent call last):
  File "/users/adbt150/miniconda3/envs/llm/lib/python3.9/site-packages/nltk/corpus/util.py", line 84, in __load
    root = nltk.data.find(f"{self.subdir}/{zip_name}")
  File "/users/adbt150/miniconda3/envs/llm/lib/python3.9/site-packages/nltk/data.py", line 583, in find
    raise LookupError(resource_not_found)
LookupError: 
**********************************************************************
  Resource [93mwordnet[0m not found.
  Please use the NLTK Downloader to obtain the resource:

  [31m>>> import nltk
  >>> nltk.download('wordnet')
  [0m
  For more information see: https://www.nltk.org/data.html

  Attempted to load [93mcorpora/wordnet.zip/wordnet/[0m

  Searched in:
    - '/users/adbt150/nltk_data'
    - '/users/adbt150/miniconda3/envs/llm/nltk_data'
    - '/users/adbt150/miniconda3/envs/llm/share/nltk_data'
    - '/users/adbt150/miniconda3/envs/llm/lib/nltk_data'
    - '/usr/share/nltk_data'
    - '/usr/local/share/nltk_data'
    - '/usr/lib/nltk_data'
    - '/usr/local/lib/nltk_data'
**********************************************************************


During handling of the above exception, another exception occurred:

Traceback (most recent call last):
  File "/users/adbt150/lm-evaluation-harness/main.py", line 117, in <module>
    main()
  File "/users/adbt150/lm-evaluation-harness/main.py", line 76, in main
    results = evaluator.simple_evaluate(
  File "/users/adbt150/lm-evaluation-harness/lm_eval/utils.py", line 243, in _wrapper
    return fn(*args, **kwargs)
  File "/users/adbt150/lm-evaluation-harness/lm_eval/evaluator.py", line 114, in simple_evaluate
    results = evaluate(
  File "/users/adbt150/lm-evaluation-harness/lm_eval/utils.py", line 243, in _wrapper
    return fn(*args, **kwargs)
  File "/users/adbt150/lm-evaluation-harness/lm_eval/evaluator.py", line 336, in evaluate
    doc['question'] = p.verbSynonyms(doc['question'])
  File "/users/adbt150/lm-evaluation-harness/lm_eval/permutations.py", line 73, in verbSynonyms
    synonyms = getSynonym(token.text)
  File "/users/adbt150/lm-evaluation-harness/lm_eval/permutations.py", line 53, in getSynonym
    synsets = wordnet.synsets(word, pos=wordnet.VERB)
  File "/users/adbt150/miniconda3/envs/llm/lib/python3.9/site-packages/nltk/corpus/util.py", line 121, in __getattr__
    self.__load()
  File "/users/adbt150/miniconda3/envs/llm/lib/python3.9/site-packages/nltk/corpus/util.py", line 86, in __load
    raise e
  File "/users/adbt150/miniconda3/envs/llm/lib/python3.9/site-packages/nltk/corpus/util.py", line 81, in __load
    root = nltk.data.find(f"{self.subdir}/{self.__name}")
  File "/users/adbt150/miniconda3/envs/llm/lib/python3.9/site-packages/nltk/data.py", line 583, in find
    raise LookupError(resource_not_found)
LookupError: 
**********************************************************************
  Resource [93mwordnet[0m not found.
  Please use the NLTK Downloader to obtain the resource:

  [31m>>> import nltk
  >>> nltk.download('wordnet')
  [0m
  For more information see: https://www.nltk.org/data.html

  Attempted to load [93mcorpora/wordnet[0m

  Searched in:
    - '/users/adbt150/nltk_data'
    - '/users/adbt150/miniconda3/envs/llm/nltk_data'
    - '/users/adbt150/miniconda3/envs/llm/share/nltk_data'
    - '/users/adbt150/miniconda3/envs/llm/lib/nltk_data'
    - '/usr/share/nltk_data'
    - '/usr/local/share/nltk_data'
    - '/usr/lib/nltk_data'
    - '/usr/local/lib/nltk_data'
**********************************************************************

[nltk_data] Downloading package punkt to /users/adbt150/nltk_data...
[nltk_data]   Package punkt is already up-to-date!
Selected Tasks: ['arc_challenge']
Loading checkpoint shards:   0%|          | 0/2 [00:00<?, ?it/s]Loading checkpoint shards:  50%|â–ˆâ–ˆâ–ˆâ–ˆâ–ˆ     | 1/2 [00:00<00:00,  8.37it/s]Loading checkpoint shards: 100%|â–ˆâ–ˆâ–ˆâ–ˆâ–ˆâ–ˆâ–ˆâ–ˆâ–ˆâ–ˆ| 2/2 [00:00<00:00,  8.71it/s]Loading checkpoint shards: 100%|â–ˆâ–ˆâ–ˆâ–ˆâ–ˆâ–ˆâ–ˆâ–ˆâ–ˆâ–ˆ| 2/2 [00:00<00:00,  8.65it/s]
Task: arc_challenge; number of docs: 1172
Traceback (most recent call last):
  File "/users/adbt150/miniconda3/envs/llm/lib/python3.9/site-packages/nltk/corpus/util.py", line 84, in __load
    root = nltk.data.find(f"{self.subdir}/{zip_name}")
  File "/users/adbt150/miniconda3/envs/llm/lib/python3.9/site-packages/nltk/data.py", line 583, in find
    raise LookupError(resource_not_found)
LookupError: 
**********************************************************************
  Resource [93mwordnet[0m not found.
  Please use the NLTK Downloader to obtain the resource:

  [31m>>> import nltk
  >>> nltk.download('wordnet')
  [0m
  For more information see: https://www.nltk.org/data.html

  Attempted to load [93mcorpora/wordnet.zip/wordnet/[0m

  Searched in:
    - '/users/adbt150/nltk_data'
    - '/users/adbt150/miniconda3/envs/llm/nltk_data'
    - '/users/adbt150/miniconda3/envs/llm/share/nltk_data'
    - '/users/adbt150/miniconda3/envs/llm/lib/nltk_data'
    - '/usr/share/nltk_data'
    - '/usr/local/share/nltk_data'
    - '/usr/lib/nltk_data'
    - '/usr/local/lib/nltk_data'
**********************************************************************


During handling of the above exception, another exception occurred:

Traceback (most recent call last):
  File "/users/adbt150/lm-evaluation-harness/main.py", line 117, in <module>
    main()
  File "/users/adbt150/lm-evaluation-harness/main.py", line 76, in main
    results = evaluator.simple_evaluate(
  File "/users/adbt150/lm-evaluation-harness/lm_eval/utils.py", line 243, in _wrapper
    return fn(*args, **kwargs)
  File "/users/adbt150/lm-evaluation-harness/lm_eval/evaluator.py", line 114, in simple_evaluate
    results = evaluate(
  File "/users/adbt150/lm-evaluation-harness/lm_eval/utils.py", line 243, in _wrapper
    return fn(*args, **kwargs)
  File "/users/adbt150/lm-evaluation-harness/lm_eval/evaluator.py", line 294, in evaluate
    doc['query'] = p.verbSynonyms(doc['query'])
  File "/users/adbt150/lm-evaluation-harness/lm_eval/permutations.py", line 73, in verbSynonyms
    synonyms = getSynonym(token.text)
  File "/users/adbt150/lm-evaluation-harness/lm_eval/permutations.py", line 53, in getSynonym
    synsets = wordnet.synsets(word, pos=wordnet.VERB)
  File "/users/adbt150/miniconda3/envs/llm/lib/python3.9/site-packages/nltk/corpus/util.py", line 121, in __getattr__
    self.__load()
  File "/users/adbt150/miniconda3/envs/llm/lib/python3.9/site-packages/nltk/corpus/util.py", line 86, in __load
    raise e
  File "/users/adbt150/miniconda3/envs/llm/lib/python3.9/site-packages/nltk/corpus/util.py", line 81, in __load
    root = nltk.data.find(f"{self.subdir}/{self.__name}")
  File "/users/adbt150/miniconda3/envs/llm/lib/python3.9/site-packages/nltk/data.py", line 583, in find
    raise LookupError(resource_not_found)
LookupError: 
**********************************************************************
  Resource [93mwordnet[0m not found.
  Please use the NLTK Downloader to obtain the resource:

  [31m>>> import nltk
  >>> nltk.download('wordnet')
  [0m
  For more information see: https://www.nltk.org/data.html

  Attempted to load [93mcorpora/wordnet[0m

  Searched in:
    - '/users/adbt150/nltk_data'
    - '/users/adbt150/miniconda3/envs/llm/nltk_data'
    - '/users/adbt150/miniconda3/envs/llm/share/nltk_data'
    - '/users/adbt150/miniconda3/envs/llm/lib/nltk_data'
    - '/usr/share/nltk_data'
    - '/usr/local/share/nltk_data'
    - '/usr/lib/nltk_data'
    - '/usr/local/lib/nltk_data'
**********************************************************************

